Workbook
Name SMIRange: #REF!

Sheet FFY25 PSoC Calculator
A1: PARENT SHARE OF COST (PSOC) ESTIMATION CALCULATOR (BCY2025) | D1: More Information
A2: 1. Enter Household Family Size (Required) | D2: What is the definition of Family Size and Household Dependents: §809.2(12)-(13)
A3: 2. Enter Monthly Income (Required) | D3: What income is excluded from family income: §809.44
A4: 3. Enter Children Receiving Child Care (Required) | D4: Number of children receiving care must be less than the family size
A6: Percent State Median Income (SMI) | B6: =Calculations!B5 -> 0 | D6: Cannot be greater than 85% to be eligible: §809.41
A7: Is the Family Eligible? | B7: =Calculations!B6 -> Yes
A9: PSoC Monthly Amount for One Child in Care (Est.) | B9: =Calculations!B8 -> 0
A10: PSoC Percent of Income for One Child | B10: =Calculations!B7 -> 0 | D10: Cannot be greater than 7% of family income: §809.19
A12: Additional Children in Care | B12: =IF(Calculations!B9=-1,0,Calculations!B9) -> 0
A13: PSoC Monthly Amount for the Additional Children (Est.) | B13: =Calculations!B11 -> 0
A14: PSoC Percent of Income for Additional Children | B14: =Calculations!B10 -> 0 | D14: Cannot be greater than 7% of family income: §809.19
A16: Total Monthly PSoC Amount (Est.) | B16: =Calculations!B13 -> 0
A17: Total Weekly PSoC Amount (Est.) | B17: =ROUND((B16/22)*5,0) -> 0
A18: Total PSoC as a Percent of Income | B18: =Calculations!B12 -> 0 | D18: Cannot be greater than 7% of family income: §809.19

Sheet PSoC Chart
B1: Parent Share of Cost (PSOC) Sliding Fee Scale (BCY2025)
A2: % State Median Income (SMI) | B2: =B63 -> 0.05 | C2: =C63 -> 0.2 | D2: =D63 -> 0.2 | E2: =E63 -> 0.3 | F2: =F63 -> 0.3 | G2: =G63 -> 0.4 | H2: =H63 -> 0.4 | I2: =I63 -> 0.5 | ... S2: =S63 -> 0.85
A3: PSOC as a % of Income - 1 Child | B3: =IF(B9>0.07,0.07,B9) -> 0.02267066 | C3: =IF(C9>0.07,0.07,C9) -> 0.032656664 | D3: =IF(D9>0.07,0.07,D9) -> 0.032667986 | E3: =IF(E9>0.07,0.07,E9) -> 0.039317996 | F3: =IF(F9>0.07,0.07,F9) -> 0.039329984 | G3: =IF(G9>0.07,0.07,G9) -> 0.045979994 | H3: =IF(H9>0.07,0.07,H9) -> 0.045991316 | I3: =IF(I9>0.07,0.07,I9) -> 0.052641326 | ... S3: =IF(S9>0.07,0.07,S9) -> 0.07
B4: Add 0.15% for each additional child up to 7% of income
B6: FAMILY SIZE: 2
A7: Monthly Income | B7: =ROUNDUP(FFY25SMI!$B3*B$63,0) -> 293 | C7: =ROUNDUP(FFY25SMI!$B3*C$63,0) -> 1170 | D7: =C7+1 -> 1171 | E7: =ROUNDUP(FFY25SMI!$B3*E$63,0) -> 1755 | F7: =E7+1 -> 1756 | G7: =ROUNDUP(FFY25SMI!$B3*G$63,0) -> 2340 | H7: =G7+1 -> 2341 | I7: =ROUNDUP(FFY25SMI!$B3*I$63,0) -> 2925 | J7: =I7+1 -> 2926 | K7: =ROUNDUP(FFY25SMI!$B3*K$63,0) -> 3510 | L7: =K7+1 -> 3511 | M7: =ROUNDUP(FFY25SMI!$B3*M$63,0) -> 4095 | N7: =M7+1 -> 4096 | O7: =ROUNDUP(FFY25SMI!$B3*O$63,0) -> 4387 | P7: =O7+1 -> 4388 | Q7: =ROUNDUP(FFY25SMI!$B3*Q$63,0) -> 4679 | R7: =Q7+1 -> 4680 | S7: =ROUND(FFY25SMI!$B3*S$63,0) -> 4971
A8: % SMI (Calculation) | B8: =ROUND(B7/FFY25SMI!$B$3,5) -> 0.0501 | C8: =ROUND(C7/FFY25SMI!$B$3,5) -> 0.20004 | D8: =ROUND(D7/FFY25SMI!$B$3,5) -> 0.20021 | E8: =ROUND(E7/FFY25SMI!$B$3,5) -> 0.30006 | F8: =ROUND(F7/FFY25SMI!$B$3,5) -> 0.30024 | G8: =ROUND(G7/FFY25SMI!$B$3,5) -> 0.40009 | H8: =ROUND(H7/FFY25SMI!$B$3,5) -> 0.40026 | I8: =ROUND(I7/FFY25SMI!$B$3,5) -> 0.50011 | ... S8: =ROUND(S7/FFY25SMI!$B$3,5) -> 0.84993
A9: PSoC % of Income (Calculation) | B9: =IF(B8<0.01,0,(((B8*100)-1)*0.000666)+0.02) -> 0.02267066 | C9: =IF(C8<0.01,0,(((C8*100)-1)*0.000666)+0.02) -> 0.032656664 | D9: =IF(D8<0.01,0,(((D8*100)-1)*0.000666)+0.02) -> 0.032667986 | E9: =IF(E8<0.01,0,(((E8*100)-1)*0.000666)+0.02) -> 0.039317996 | F9: =IF(F8<0.01,0,(((F8*100)-1)*0.000666)+0.02) -> 0.039329984 | G9: =IF(G8<0.01,0,(((G8*100)-1)*0.000666)+0.02) -> 0.045979994 | H9: =IF(H8<0.01,0,(((H8*100)-1)*0.000666)+0.02) -> 0.045991316 | I9: =IF(I8<0.01,0,(((I8*100)-1)*0.000666)+0.02) -> 0.052641326 | ... S9: =IF(S8<0.01,0,(((S8*100)-1)*0.000666)+0.02) -> 0.075939338
A10: PSoC 7% Cap (Calculation) | B10: =ROUND(B7*0.07,0) -> 21 | C10: =ROUND(C7*0.07,0) -> 82 | D10: =ROUND(D7*0.07,0) -> 82 | E10: =ROUND(E7*0.07,0) -> 123 | F10: =ROUND(F7*0.07,0) -> 123 | G10: =ROUND(G7*0.07,0) -> 164 | H10: =ROUND(H7*0.07,0) -> 164 | I10: =ROUND(I7*0.07,0) -> 205 | ... S10: =ROUND(S7*0.07,0) -> 348
A11: Monthly PSoC (Calculation) | B11: =B9*B7 -> 6.6425034 | C11: =C9*C7 -> 38.208297 | D11: =D9*D7 -> 38.254212 | E11: =E9*E7 -> 69.003083 | F11: =F9*F7 -> 69.063452 | G11: =G9*G7 -> 107.59319 | H11: =H9*H7 -> 107.66567 | I11: =I9*I7 -> 153.97588 | ... S11: =S9*S7 -> 377.49445
A12: Total PSoC 7% Cap (Calculation) | B12: =IF(B9>0.07,0.07,B9) -> 0.02267066 | C12: =IF(C9>0.07,0.07,C9) -> 0.032656664 | D12: =IF(D9>0.07,0.07,D9) -> 0.032667986 | E12: =IF(E9>0.07,0.07,E9) -> 0.039317996 | F12: =IF(F9>0.07,0.07,F9) -> 0.039329984 | G12: =IF(G9>0.07,0.07,G9) -> 0.045979994 | H12: =IF(H9>0.07,0.07,H9) -> 0.045991316 | I12: =IF(I9>0.07,0.07,I9) -> 0.052641326 | ... S12: =IF(S9>0.07,0.07,S9) -> 0.07
A13: Monthly PSoC | B13: =IF(ROUND(B11,0)>B10,B10,ROUND(B11,0)) -> 7 | C13: =IF(ROUND(C11,0)>C10,C10,ROUND(C11,0)) -> 38 | D13: =IF(ROUND(D11,0)>D10,D10,ROUND(D11,0)) -> 38 | E13: =IF(ROUND(E11,0)>E10,E10,ROUND(E11,0)) -> 69 | F13: =IF(ROUND(F11,0)>F10,F10,ROUND(F11,0)) -> 69 | G13: =IF(ROUND(G11,0)>G10,G10,ROUND(G11,0)) -> 108 | H13: =IF(ROUND(H11,0)>H10,H10,ROUND(H11,0)) -> 108 | I13: =IF(ROUND(I11,0)>I10,I10,ROUND(I11,0)) -> 154 | ... S13: =IF(ROUND(S11,0)>S10,S10,ROUND(S11,0)) -> 348
A14: Weekly PSoC | B14: =ROUND((B13/22)*5,0) -> 2 | C14: =ROUND((C13/22)*5,0) -> 9 | D14: =ROUND((D13/22)*5,0) -> 9 | E14: =ROUND((E13/22)*5,0) -> 16 | F14: =ROUND((F13/22)*5,0) -> 16 | G14: =ROUND((G13/22)*5,0) -> 25 | H14: =ROUND((H13/22)*5,0) -> 25 | I14: =ROUND((I13/22)*5,0) -> 35 | ... S14: =ROUND((S13/22)*5,0) -> 79
B16: FAMILY SIZE: 3
A17: Monthly Income | B17: =ROUNDUP(FFY25SMI!$B4*B$63,0) -> 362 | C17: =ROUNDUP(FFY25SMI!$B4*C$63,0) -> 1445 | D17: =C17+1 -> 1446 | E17: =ROUNDUP(FFY25SMI!$B4*E$63,0) -> 2168 | F17: =E17+1 -> 2169 | G17: =ROUNDUP(FFY25SMI!$B4*G$63,0) -> 2890 | H17: =G17+1 -> 2891 | I17: =ROUNDUP(FFY25SMI!$B4*I$63,0) -> 3613 | J17: =I17+1 -> 3614 | K17: =ROUNDUP(FFY25SMI!$B4*K$63,0) -> 4335 | L17: =K17+1 -> 4336 | M17: =ROUNDUP(FFY25SMI!$B4*M$63,0) -> 5058 | N17: =M17+1 -> 5059 | O17: =ROUNDUP(FFY25SMI!$B4*O$63,0) -> 5419 | P17: =O17+1 -> 5420 | Q17: =ROUNDUP(FFY25SMI!$B4*Q$63,0) -> 5780 | R17: =Q17+1 -> 5781 | S17: =ROUND(FFY25SMI!$B4*S$63,0) -> 6141
A18: % SMI (Calculation) | B18: =ROUND(B17/FFY25SMI!$B$4,5) -> 0.0501 | C18: =ROUND(C17/FFY25SMI!$B$4,5) -> 0.2 | D18: =ROUND(D17/FFY25SMI!$B$4,5) -> 0.20014 | E18: =ROUND(E17/FFY25SMI!$B$4,5) -> 0.30007 | F18: =ROUND(F17/FFY25SMI!$B$4,5) -> 0.30021 | G18: =ROUND(G17/FFY25SMI!$B$4,5) -> 0.4 | H18: =ROUND(H17/FFY25SMI!$B$4,5) -> 0.40014 | I18: =ROUND(I17/FFY25SMI!$B$4,5) -> 0.50008 | ... S18: =ROUND(S17/FFY25SMI!$B$4,5) -> 0.84998
A19: PSoC % of Income (Calculation) | B19: =IF(B18<0.01,0,(((B18*100)-1)*0.000666)+0.02) -> 0.02267066 | C19: =IF(C18<0.01,0,(((C18*100)-1)*0.000666)+0.02) -> 0.032654 | D19: =IF(D18<0.01,0,(((D18*100)-1)*0.000666)+0.02) -> 0.032663324 | E19: =IF(E18<0.01,0,(((E18*100)-1)*0.000666)+0.02) -> 0.039318662 | F19: =IF(F18<0.01,0,(((F18*100)-1)*0.000666)+0.02) -> 0.039327986 | G19: =IF(G18<0.01,0,(((G18*100)-1)*0.000666)+0.02) -> 0.045974 | H19: =IF(H18<0.01,0,(((H18*100)-1)*0.000666)+0.02) -> 0.045983324 | I19: =IF(I18<0.01,0,(((I18*100)-1)*0.000666)+0.02) -> 0.052639328 | ... S19: =IF(S18<0.01,0,(((S18*100)-1)*0.000666)+0.02) -> 0.075942668
A20: PSoC 7% Cap (Calculation) | B20: =ROUND(B17*0.07,0) -> 25 | C20: =ROUND(C17*0.07,0) -> 101 | D20: =ROUND(D17*0.07,0) -> 101 | E20: =ROUND(E17*0.07,0) -> 152 | F20: =ROUND(F17*0.07,0) -> 152 | G20: =ROUND(G17*0.07,0) -> 202 | H20: =ROUND(H17*0.07,0) -> 202 | I20: =ROUND(I17*0.07,0) -> 253 | ... S20: =ROUND(S17*0.07,0) -> 430
A21: PSoC - 1st Child(Calculation) | B21: =B19*B17 -> 8.2067789 | C21: =C19*C17 -> 47.18503 | D21: =D19*D17 -> 47.231167 | E21: =E19*E17 -> 85.242859 | F21: =F19*F17 -> 85.302402 | G21: =G19*G17 -> 132.86486 | H21: =H19*H17 -> 132.93779 | I21: =I19*I17 -> 190.18589 | ... S21: =S19*S17 -> 466.36392
A22: PSoC % of Income-2nd Child (Calculation) | B22: =B18*0.015 -> 0.0007515 | C22: =C18*0.015 -> 0.003 | D22: =D18*0.015 -> 0.0030021 | E22: =E18*0.015 -> 0.00450105 | F22: =F18*0.015 -> 0.00450315 | G22: =G18*0.015 -> 0.006 | H22: =H18*0.015 -> 0.0060021 | I22: =I18*0.015 -> 0.0075012 | ... S22: =S18*0.015 -> 0.0127497
A23: Total PSoC % of Income (Calculation) | B23: =B19+B22 -> 0.02342216 | C23: =C19+C22 -> 0.035654 | D23: =D19+D22 -> 0.035665424 | E23: =E19+E22 -> 0.043819712 | F23: =F19+F22 -> 0.043831136 | G23: =G19+G22 -> 0.051974 | H23: =H19+H22 -> 0.051985424 | I23: =I19+I22 -> 0.060140528 | ... S23: =S19+S22 -> 0.088692368
A24: Total PSoC 7% Cap (Calculation) | B24: =IF(B23>0.07,0.07,B23) -> 0.02342216 | C24: =IF(C23>0.07,0.07,C23) -> 0.035654 | D24: =IF(D23>0.07,0.07,D23) -> 0.035665424 | E24: =IF(E23>0.07,0.07,E23) -> 0.043819712 | F24: =IF(F23>0.07,0.07,F23) -> 0.043831136 | G24: =IF(G23>0.07,0.07,G23) -> 0.051974 | H24: =IF(H23>0.07,0.07,H23) -> 0.051985424 | I24: =IF(I23>0.07,0.07,I23) -> 0.060140528 | ... S24: =IF(S23>0.07,0.07,S23) -> 0.07
A25: Monthly PSoC - 1st Child | B25: =IF(ROUND(B21,0)>B20,B20,ROUND(B21,0)) -> 8 | C25: =IF(ROUND(C21,0)>C20,C20,ROUND(C21,0)) -> 47 | D25: =IF(ROUND(D21,0)>D20,D20,ROUND(D21,0)) -> 47 | E25: =IF(ROUND(E21,0)>E20,E20,ROUND(E21,0)) -> 85 | F25: =IF(ROUND(F21,0)>F20,F20,ROUND(F21,0)) -> 85 | G25: =IF(ROUND(G21,0)>G20,G20,ROUND(G21,0)) -> 133 | H25: =IF(ROUND(H21,0)>H20,H20,ROUND(H21,0)) -> 133 | I25: =IF(ROUND(I21,0)>I20,I20,ROUND(I21,0)) -> 190 | ... S25: =IF(ROUND(S21,0)>S20,S20,ROUND(S21,0)) -> 430
A26: Monthly PSoC - 2nd Child | B26: =B27-B25 -> 0 | C26: =C27-C25 -> 5 | D26: =D27-D25 -> 5 | E26: =E27-E25 -> 10 | F26: =F27-F25 -> 10 | G26: =G27-G25 -> 17 | H26: =H27-H25 -> 17 | I26: =I27-I25 -> 27 | ... S26: =S27-S25 -> 0
A27: Monthly Total PSoC | B27: =ROUND(B24*B17,0) -> 8 | C27: =ROUND(C24*C17,0) -> 52 | D27: =ROUND(D24*D17,0) -> 52 | E27: =ROUND(E24*E17,0) -> 95 | F27: =ROUND(F24*F17,0) -> 95 | G27: =ROUND(G24*G17,0) -> 150 | H27: =ROUND(H24*H17,0) -> 150 | I27: =ROUND(I24*I17,0) -> 217 | ... S27: =ROUND(S24*S17,0) -> 430
A28: Weekly PSoC - 1st Child | B28: =ROUND((B25/22)*5,0) -> 2 | C28: =ROUND((C25/22)*5,0) -> 11 | D28: =ROUND((D25/22)*5,0) -> 11 | E28: =ROUND((E25/22)*5,0) -> 19 | F28: =ROUND((F25/22)*5,0) -> 19 | G28: =ROUND((G25/22)*5,0) -> 30 | H28: =ROUND((H25/22)*5,0) -> 30 | I28: =ROUND((I25/22)*5,0) -> 43 | ... S28: =ROUND((S25/22)*5,0) -> 98
A29: Weekly PSoC - 2nd Child | B29: =ROUND(((B27/22)*5)-B28,0) -> 0 | C29: =ROUND(((C27/22)*5)-C28,0) -> 1 | D29: =ROUND(((D27/22)*5)-D28,0) -> 1 | E29: =ROUND(((E27/22)*5)-E28,0) -> 3 | F29: =ROUND(((F27/22)*5)-F28,0) -> 3 | G29: =ROUND(((G27/22)*5)-G28,0) -> 4 | H29: =ROUND(((H27/22)*5)-H28,0) -> 4 | I29: =ROUND(((I27/22)*5)-I28,0) -> 6 | ... S29: =ROUND(((S27/22)*5)-S28,0) -> 0
B31: FAMILY SIZE: 4
A32: Monthly Income | B32: =ROUNDUP(FFY25SMI!$B5*B$63,0) -> 431 | C32: =ROUNDUP(FFY25SMI!$B5*C$63,0) -> 1721 | D32: =ROUNDUP(FFY25SMI!$B5*D$63,0) -> 1721 | E32: =ROUNDUP(FFY25SMI!$B5*E$63,0) -> 2581 | F32: =ROUNDUP(FFY25SMI!$B5*F$63,0) -> 2581 | G32: =ROUNDUP(FFY25SMI!$B5*G$63,0) -> 3441 | H32: =ROUNDUP(FFY25SMI!$B5*H$63,0) -> 3441 | I32: =ROUNDUP(FFY25SMI!$B5*I$63,0) -> 4301 | ... Q32: =ROUNDUP(FFY25SMI!$B5*Q$63,0) -> 6881 | R32: =Q32+1 -> 6882 | S32: =ROUND(FFY25SMI!$B5*S$63,0) -> 7311
A33: % SMI (Calculation) | B33: =ROUND(B32/FFY25SMI!$B$5,5) -> 0.05011 | C33: =ROUND(C32/FFY25SMI!$B$5,5) -> 0.20009 | D33: =ROUND(D32/FFY25SMI!$B$5,5) -> 0.20009 | E33: =ROUND(E32/FFY25SMI!$B$5,5) -> 0.30008 | F33: =ROUND(F32/FFY25SMI!$B$5,5) -> 0.30008 | G33: =ROUND(G32/FFY25SMI!$B$5,5) -> 0.40007 | H33: =ROUND(H32/FFY25SMI!$B$5,5) -> 0.40007 | I33: =ROUND(I32/FFY25SMI!$B$5,5) -> 0.50005 | ... S33: =ROUND(S32/FFY25SMI!$B$5,5) -> 0.85001
A34: PSoC % of Income (Calculation) | B34: =IF(B33<0.01,0,(((B33*100)-1)*0.000666)+0.02) -> 0.022671326 | C34: =IF(C33<0.01,0,(((C33*100)-1)*0.000666)+0.02) -> 0.032659994 | D34: =IF(D33<0.01,0,(((D33*100)-1)*0.000666)+0.02) -> 0.032659994 | E34: =IF(E33<0.01,0,(((E33*100)-1)*0.000666)+0.02) -> 0.039319328 | F34: =IF(F33<0.01,0,(((F33*100)-1)*0.000666)+0.02) -> 0.039319328 | G34: =IF(G33<0.01,0,(((G33*100)-1)*0.000666)+0.02) -> 0.045978662 | H34: =IF(H33<0.01,0,(((H33*100)-1)*0.000666)+0.02) -> 0.045978662 | I34: =IF(I33<0.01,0,(((I33*100)-1)*0.000666)+0.02) -> 0.05263733 | ... S34: =IF(S33<0.01,0,(((S33*100)-1)*0.000666)+0.02) -> 0.075944666
A35: PSoC 7% Cap (Calculation) | B35: =ROUND(B32*0.07,0) -> 30 | C35: =ROUND(C32*0.07,0) -> 120 | D35: =ROUND(D32*0.07,0) -> 120 | E35: =ROUND(E32*0.07,0) -> 181 | F35: =ROUND(F32*0.07,0) -> 181 | G35: =ROUND(G32*0.07,0) -> 241 | H35: =ROUND(H32*0.07,0) -> 241 | I35: =ROUND(I32*0.07,0) -> 301 | ... S35: =ROUND(S32*0.07,0) -> 512
A36: PSoC - 1st Child(Calculation) | B36: =B34*B32 -> 9.7713415 | C36: =C34*C32 -> 56.20785 | D36: =D34*D32 -> 56.20785 | E36: =E34*E32 -> 101.48319 | F36: =F34*F32 -> 101.48319 | G36: =G34*G32 -> 158.21258 | H36: =H34*H32 -> 158.21258 | I36: =I34*I32 -> 226.39316 | ... S36: =S34*S32 -> 555.23145
A37: PSoC % of Income-2nd Child (Calculation) | B37: =B33*0.015 -> 0.00075165 | C37: =C33*0.015 -> 0.00300135 | D37: =D33*0.015 -> 0.00300135 | E37: =E33*0.015 -> 0.0045012 | F37: =F33*0.015 -> 0.0045012 | G37: =G33*0.015 -> 0.00600105 | H37: =H33*0.015 -> 0.00600105 | I37: =I33*0.015 -> 0.00750075 | ... S37: =S33*0.015 -> 0.01275015
A38: Total PSoC % of Income (Calculation) | B38: =B34+B37 -> 0.023422976 | C38: =C34+C37 -> 0.035661344 | D38: =D34+D37 -> 0.035661344 | E38: =E34+E37 -> 0.043820528 | F38: =F34+F37 -> 0.043820528 | G38: =G34+G37 -> 0.051979712 | H38: =H34+H37 -> 0.051979712 | I38: =I34+I37 -> 0.06013808 | ... S38: =S34+S37 -> 0.088694816
A39: Total PSoC 7% Cap (Calculation) | B39: =IF(B38>0.07,0.07,B38) -> 0.023422976 | C39: =IF(C38>0.07,0.07,C38) -> 0.035661344 | D39: =IF(D38>0.07,0.07,D38) -> 0.035661344 | E39: =IF(E38>0.07,0.07,E38) -> 0.043820528 | F39: =IF(F38>0.07,0.07,F38) -> 0.043820528 | G39: =IF(G38>0.07,0.07,G38) -> 0.051979712 | H39: =IF(H38>0.07,0.07,H38) -> 0.051979712 | I39: =IF(I38>0.07,0.07,I38) -> 0.06013808 | ... S39: =IF(S38>0.07,0.07,S38) -> 0.07
A40: Monthly PSoC - 1st Child | B40: =IF(ROUND(B36,0)>B35,B35,ROUND(B36,0)) -> 10 | C40: =IF(ROUND(C36,0)>C35,C35,ROUND(C36,0)) -> 56 | D40: =IF(ROUND(D36,0)>D35,D35,ROUND(D36,0)) -> 56 | E40: =IF(ROUND(E36,0)>E35,E35,ROUND(E36,0)) -> 101 | F40: =IF(ROUND(F36,0)>F35,F35,ROUND(F36,0)) -> 101 | G40: =IF(ROUND(G36,0)>G35,G35,ROUND(G36,0)) -> 158 | H40: =IF(ROUND(H36,0)>H35,H35,ROUND(H36,0)) -> 158 | I40: =IF(ROUND(I36,0)>I35,I35,ROUND(I36,0)) -> 226 | ... S40: =IF(ROUND(S36,0)>S35,S35,ROUND(S36,0)) -> 512
A41: Monthly PSoC - 2nd Child | B41: =B42-B40 -> 0 | C41: =C42-C40 -> 5 | D41: =D42-D40 -> 5 | E41: =E42-E40 -> 12 | F41: =F42-F40 -> 12 | G41: =G42-G40 -> 21 | H41: =H42-H40 -> 21 | I41: =I42-I40 -> 33 | ... S41: =S42-S40 -> 0
A42: Monthly Total PSoC | B42: =ROUND(B39*B32,0) -> 10 | C42: =ROUND(C39*C32,0) -> 61 | D42: =ROUND(D39*D32,0) -> 61 | E42: =ROUND(E39*E32,0) -> 113 | F42: =ROUND(F39*F32,0) -> 113 | G42: =ROUND(G39*G32,0) -> 179 | H42: =ROUND(H39*H32,0) -> 179 | I42: =ROUND(I39*I32,0) -> 259 | ... S42: =ROUND(S39*S32,0) -> 512
A43: Weekly PSoC - 1st Child | B43: =ROUND((B40/22)*5,0) -> 2 | C43: =ROUND((C40/22)*5,0) -> 13 | D43: =ROUND((D40/22)*5,0) -> 13 | E43: =ROUND((E40/22)*5,0) -> 23 | F43: =ROUND((F40/22)*5,0) -> 23 | G43: =ROUND((G40/22)*5,0) -> 36 | H43: =ROUND((H40/22)*5,0) -> 36 | I43: =ROUND((I40/22)*5,0) -> 51 | ... S43: =ROUND((S40/22)*5,0) -> 116
...

Sheet Calculations
A1: PARENT SHARE OF COST CALCULATOR | D1: Calculations | G1: Notes
A2: Enter Family Size | B2: ='FFY25 PSoC Calculator'!B2 -> 0 | G2: 1. Enter Family Size
A3: Enter Monthly Income | B3: ='FFY25 PSoC Calculator'!B3 -> 0 | G3: 2. Enter Monthly Income
A4: Enter Children In Care | B4: ='FFY25 PSoC Calculator'!B4 -> 0 | C4: =IF(OR(B2<B4,B2=B4),"ERROR - Children in care must be less than the family size."," ") -> ERROR - Children in care must be less than the family size. | G4: 3. Enter Children Receiving CCS (must be less than the family size)
A5: % SMI | B5: =IFERROR(ROUND(B3/(VLOOKUP(B2,SMI[],2,FALSE)),5),0) -> 0 | G5: 4. % SMI for family size and income
A6: Family Eligible | B6: =IF(B5>0.85004,"No","Yes") -> Yes | G6: 5. Not eligible if % SMI is greater than 85%
A7: PSoC% - 1 Child | B7: =IF(B6="no","",F7) -> 0 | D7: =IF(B5<0.01,0,(((B5*100)-1)*0.000666)+0.02) -> 0 | E7: =IF(B6="No","",D7) -> 0 | F7: =IF(D7>0.07,0.07,E7) -> 0 | G7: 6. If eligible (B6) and income is less than 1% SMI (B8), D7: % SMI minus 1 to get 1% to 0, multiply result by .066%, add 2 percentage points to start scale at 2% of income.E2: if B6 is not eligible, result is null; if eligible, result is D7 calculation; F7: if D7 result is greater than 7%, cap result at 7% of income
A8: PSoC - 1 Child | B8: =IF(B6="Yes",(ROUND(B7*B3,0)),0) -> 0 | G8: 7. If eligible (B6), multiply monthly income (B3) by PSoC % income result for the first child (B7), rounded to nearest $
A9: Add'l Children | B9: =IF(B6="no","",(B4-1)) -> -1 | G9: 8. If eligible (B6), additional children = children in care minus the first child
A10: PSoC% Add'l Children | B10: =IF(B6="no","",D10) -> 0 | D10: =IF(F7=0.07,0,(B5*0.015)*B9) -> 0 | E10: =IF(B7+B10>0.07,"Y","N") -> N | F10: =IF(E10="N",D10,0.07) -> 0 | G10: 9. If eligible (B6), perform calcuation at D10. D10: if % for 1 child is 7%, then no additional amount; if less than 7%, then multiply % SMI (B5) by 1.5% for addt'l child, multiply result by the total number of additional children (B9). E10: Yes, if total PSoC% (B7+B10) is greater than 7%, No, if less than 7%. F10: if total PSoC% is less than 7%, then result is the additional child calculation at D10
A11: PSoC - Add'l Children | B11: =IF(B6="no","",(B13-B8)) -> 0 | G11: 12. If eligible (B6), subtract the PSoC amount for 1 child (B8) from the total PSoC (B13) to get the amount for additional children
A12: Total PSoC % | B12: =IF(B6="no","",E12) -> 0 | D12: =IF(B6="no","",(B7+B10)) -> 0 | E12: =IF(D12>0.07,0.07,D12) -> 0 | G12: 10. If elgibile (B6), D12: add PSoC % for 1 child (B7) , plus the PSoC % for additional children (B10) to get the total PSoC%; E12: if total PSoC% (D12) is greater than 7%, cap the % at 7%.
A13: TOTAL PSOC | B13: =IF(B6="no","",(ROUND(B12*B3,0))) -> 0 | G13: 11. If eligible (B6), multiply the total PSoC % (B12) by monthly income (B3) to get the total PSoC amount
A21: =IFERROR(ROUND(B3/(VLOOKUP(B2,SMI[],2,FALSE)),4),0) -> 0
H25: 0.000666
H26: 0.015
H30: 0.000666

Sheet FFY25SMI
A1: Family Size | B1: 100% SMI per Family Size
A2: 1 | B2: 4472.5633 | E2: 4472.5633 | F2: =ROUND(E2,0) -> 4473
A3: 2 | B3: 5848.7367 | E3: 5848.7367 | F3: =ROUND(E3,0) -> 5849
A4: 3 | B4: 7224.91 | E4: 7224.91 | F4: =ROUND(E4,0) -> 7225
A5: 4 | B5: 8601.0833 | E5: 8601.0833 | F5: =ROUND(E5,0) -> 8601
A6: 5 | B6: 9977.2567 | E6: 9977.2567 | F6: =ROUND(E6,0) -> 9977
A7: 6 | B7: 11353.43 | E7: 11353.43 | F7: =ROUND(E7,0) -> 11353
A8: 7 | B8: 11611.463 | E8: 11611.463 | F8: =ROUND(E8,0) -> 11611
A9: 8 | B9: 11869.495 | E9: 11869.495 | F9: =ROUND(E9,0) -> 11869
A10: 9 | B10: 12127.528 | E10: 12127.528 | F10: =ROUND(E10,0) -> 12128
A11: 10 | B11: 12385.56 | E11: 12385.56 | F11: =ROUND(E11,0) -> 12386
A12: 11 | B12: 12643.593 | E12: 12643.593 | F12: =ROUND(E12,0) -> 12644
A13: 12 | B13: 12901.625 | E13: 12901.625 | F13: =ROUND(E13,0) -> 12902
... A16: 15 | B16: 13675.723 | E16: 13675.723 | F16: =ROUND(E16,0) -> 13676
